2025-09-25 14:59:53,312 INFO    MainThread:2392 [wandb_setup.py:_flush():80] Current SDK version is 0.21.1
2025-09-25 14:59:53,312 INFO    MainThread:2392 [wandb_setup.py:_flush():80] Configure stats pid to 2392
2025-09-25 14:59:53,312 INFO    MainThread:2392 [wandb_setup.py:_flush():80] Loading settings from C:\Users\faiso\.config\wandb\settings
2025-09-25 14:59:53,312 INFO    MainThread:2392 [wandb_setup.py:_flush():80] Loading settings from D:\COMP702\DIFUSCO-main\difusco\wandb\settings
2025-09-25 14:59:53,312 INFO    MainThread:2392 [wandb_setup.py:_flush():80] Loading settings from environment variables
2025-09-25 14:59:53,312 INFO    MainThread:2392 [wandb_init.py:setup_run_log_directory():703] Logging user logs to results\models\wandb\run-20250925_145953-s775d5ji\logs\debug.log
2025-09-25 14:59:53,326 INFO    MainThread:2392 [wandb_init.py:setup_run_log_directory():704] Logging internal logs to results\models\wandb\run-20250925_145953-s775d5ji\logs\debug-internal.log
2025-09-25 14:59:53,326 INFO    MainThread:2392 [wandb_init.py:init():830] calling init triggers
2025-09-25 14:59:53,326 INFO    MainThread:2392 [wandb_init.py:init():835] wandb.init called with sweep_config: {}
config: {'_wandb': {}}
2025-09-25 14:59:53,326 INFO    MainThread:2392 [wandb_init.py:init():871] starting backend
2025-09-25 14:59:53,545 INFO    MainThread:2392 [wandb_init.py:init():874] sending inform_init request
2025-09-25 14:59:53,586 INFO    MainThread:2392 [wandb_init.py:init():882] backend started and connected
2025-09-25 14:59:53,590 INFO    MainThread:2392 [wandb_init.py:init():953] updated telemetry
2025-09-25 14:59:53,591 INFO    MainThread:2392 [wandb_init.py:init():977] communicating run to backend with 90.0 second timeout
2025-09-25 14:59:54,377 INFO    MainThread:2392 [wandb_init.py:init():1029] starting run threads in backend
2025-09-25 14:59:54,513 INFO    MainThread:2392 [wandb_run.py:_console_start():2494] atexit reg
2025-09-25 14:59:54,514 INFO    MainThread:2392 [wandb_run.py:_redirect():2342] redirect: wrap_raw
2025-09-25 14:59:54,514 INFO    MainThread:2392 [wandb_run.py:_redirect():2411] Wrapping output streams.
2025-09-25 14:59:54,514 INFO    MainThread:2392 [wandb_run.py:_redirect():2434] Redirects installed.
2025-09-25 14:59:54,516 INFO    MainThread:2392 [wandb_init.py:init():1075] run started, returning control to user process
2025-09-25 15:20:48,704 INFO    MsgRouterThr:2392 [mailbox.py:close():129] [no run ID] Closing mailbox, abandoning 1 handles.
2025-09-25 15:20:50,408 ERROR   MainThread:2392 [redirect.py:_on_write():664] [all runs] error in stdout callback
Traceback (most recent call last):
  File "C:\Users\faiso\AppData\Local\Programs\Python\Python312\Lib\site-packages\wandb\sdk\lib\redirect.py", line 662, in _on_write
    cb(written_data)
  File "C:\Users\faiso\AppData\Local\Programs\Python\Python312\Lib\site-packages\wandb\sdk\wandb_run.py", line 2415, in <lambda>
    lambda data: self._console_raw_callback("stdout", data),
                 ^^^^^^^^^^^^^^^^^^^^^^^^^^^^^^^^^^^^^^^^^^
  File "C:\Users\faiso\AppData\Local\Programs\Python\Python312\Lib\site-packages\wandb\sdk\wandb_run.py", line 399, in wrapper
    return func(self, *args, **kwargs)
           ^^^^^^^^^^^^^^^^^^^^^^^^^^^
  File "C:\Users\faiso\AppData\Local\Programs\Python\Python312\Lib\site-packages\wandb\sdk\wandb_run.py", line 457, in wrapper_fn
    return func(self, *args, **kwargs)
           ^^^^^^^^^^^^^^^^^^^^^^^^^^^
  File "C:\Users\faiso\AppData\Local\Programs\Python\Python312\Lib\site-packages\wandb\sdk\wandb_run.py", line 1583, in _console_raw_callback
    self._backend.interface.publish_output_raw(name, data)
  File "C:\Users\faiso\AppData\Local\Programs\Python\Python312\Lib\site-packages\wandb\sdk\interface\interface.py", line 771, in publish_output_raw
    self._publish_output_raw(o)
  File "C:\Users\faiso\AppData\Local\Programs\Python\Python312\Lib\site-packages\wandb\sdk\interface\interface_shared.py", line 38, in _publish_output_raw
    self._publish(rec)
  File "C:\Users\faiso\AppData\Local\Programs\Python\Python312\Lib\site-packages\wandb\sdk\interface\interface_sock.py", line 39, in _publish
    self._sock_client.send_record_publish(record)
  File "C:\Users\faiso\AppData\Local\Programs\Python\Python312\Lib\site-packages\wandb\sdk\lib\sock_client.py", line 166, in send_record_publish
    self.send_server_request(server_req)
  File "C:\Users\faiso\AppData\Local\Programs\Python\Python312\Lib\site-packages\wandb\sdk\lib\sock_client.py", line 146, in send_server_request
    self._send_message(msg)
  File "C:\Users\faiso\AppData\Local\Programs\Python\Python312\Lib\site-packages\wandb\sdk\lib\sock_client.py", line 143, in _send_message
    self._sendall_with_error_handle(header + data)
  File "C:\Users\faiso\AppData\Local\Programs\Python\Python312\Lib\site-packages\wandb\sdk\lib\sock_client.py", line 122, in _sendall_with_error_handle
    sent = self._sock.send(data)
           ^^^^^^^^^^^^^^^^^^^^^
ConnectionAbortedError: [WinError 10053] An established connection was aborted by the software in your host machine
2025-09-25 15:20:50,420 ERROR   MainThread:2392 [redirect.py:_on_write():664] [all runs] error in stdout callback
Traceback (most recent call last):
  File "C:\Users\faiso\AppData\Local\Programs\Python\Python312\Lib\site-packages\wandb\sdk\lib\redirect.py", line 662, in _on_write
    cb(written_data)
  File "C:\Users\faiso\AppData\Local\Programs\Python\Python312\Lib\site-packages\wandb\sdk\wandb_run.py", line 2415, in <lambda>
    lambda data: self._console_raw_callback("stdout", data),
                 ^^^^^^^^^^^^^^^^^^^^^^^^^^^^^^^^^^^^^^^^^^
  File "C:\Users\faiso\AppData\Local\Programs\Python\Python312\Lib\site-packages\wandb\sdk\wandb_run.py", line 399, in wrapper
    return func(self, *args, **kwargs)
           ^^^^^^^^^^^^^^^^^^^^^^^^^^^
  File "C:\Users\faiso\AppData\Local\Programs\Python\Python312\Lib\site-packages\wandb\sdk\wandb_run.py", line 457, in wrapper_fn
    return func(self, *args, **kwargs)
           ^^^^^^^^^^^^^^^^^^^^^^^^^^^
  File "C:\Users\faiso\AppData\Local\Programs\Python\Python312\Lib\site-packages\wandb\sdk\wandb_run.py", line 1583, in _console_raw_callback
    self._backend.interface.publish_output_raw(name, data)
  File "C:\Users\faiso\AppData\Local\Programs\Python\Python312\Lib\site-packages\wandb\sdk\interface\interface.py", line 771, in publish_output_raw
    self._publish_output_raw(o)
  File "C:\Users\faiso\AppData\Local\Programs\Python\Python312\Lib\site-packages\wandb\sdk\interface\interface_shared.py", line 38, in _publish_output_raw
    self._publish(rec)
  File "C:\Users\faiso\AppData\Local\Programs\Python\Python312\Lib\site-packages\wandb\sdk\interface\interface_sock.py", line 39, in _publish
    self._sock_client.send_record_publish(record)
  File "C:\Users\faiso\AppData\Local\Programs\Python\Python312\Lib\site-packages\wandb\sdk\lib\sock_client.py", line 166, in send_record_publish
    self.send_server_request(server_req)
  File "C:\Users\faiso\AppData\Local\Programs\Python\Python312\Lib\site-packages\wandb\sdk\lib\sock_client.py", line 146, in send_server_request
    self._send_message(msg)
  File "C:\Users\faiso\AppData\Local\Programs\Python\Python312\Lib\site-packages\wandb\sdk\lib\sock_client.py", line 143, in _send_message
    self._sendall_with_error_handle(header + data)
  File "C:\Users\faiso\AppData\Local\Programs\Python\Python312\Lib\site-packages\wandb\sdk\lib\sock_client.py", line 122, in _sendall_with_error_handle
    sent = self._sock.send(data)
           ^^^^^^^^^^^^^^^^^^^^^
ConnectionAbortedError: [WinError 10053] An established connection was aborted by the software in your host machine
2025-09-25 15:20:50,420 ERROR   MainThread:2392 [redirect.py:_on_write():664] [all runs] error in stdout callback
Traceback (most recent call last):
  File "C:\Users\faiso\AppData\Local\Programs\Python\Python312\Lib\site-packages\wandb\sdk\lib\redirect.py", line 662, in _on_write
    cb(written_data)
  File "C:\Users\faiso\AppData\Local\Programs\Python\Python312\Lib\site-packages\wandb\sdk\wandb_run.py", line 2415, in <lambda>
    lambda data: self._console_raw_callback("stdout", data),
                 ^^^^^^^^^^^^^^^^^^^^^^^^^^^^^^^^^^^^^^^^^^
  File "C:\Users\faiso\AppData\Local\Programs\Python\Python312\Lib\site-packages\wandb\sdk\wandb_run.py", line 399, in wrapper
    return func(self, *args, **kwargs)
           ^^^^^^^^^^^^^^^^^^^^^^^^^^^
  File "C:\Users\faiso\AppData\Local\Programs\Python\Python312\Lib\site-packages\wandb\sdk\wandb_run.py", line 457, in wrapper_fn
    return func(self, *args, **kwargs)
           ^^^^^^^^^^^^^^^^^^^^^^^^^^^
  File "C:\Users\faiso\AppData\Local\Programs\Python\Python312\Lib\site-packages\wandb\sdk\wandb_run.py", line 1583, in _console_raw_callback
    self._backend.interface.publish_output_raw(name, data)
  File "C:\Users\faiso\AppData\Local\Programs\Python\Python312\Lib\site-packages\wandb\sdk\interface\interface.py", line 771, in publish_output_raw
    self._publish_output_raw(o)
  File "C:\Users\faiso\AppData\Local\Programs\Python\Python312\Lib\site-packages\wandb\sdk\interface\interface_shared.py", line 38, in _publish_output_raw
    self._publish(rec)
  File "C:\Users\faiso\AppData\Local\Programs\Python\Python312\Lib\site-packages\wandb\sdk\interface\interface_sock.py", line 39, in _publish
    self._sock_client.send_record_publish(record)
  File "C:\Users\faiso\AppData\Local\Programs\Python\Python312\Lib\site-packages\wandb\sdk\lib\sock_client.py", line 166, in send_record_publish
    self.send_server_request(server_req)
  File "C:\Users\faiso\AppData\Local\Programs\Python\Python312\Lib\site-packages\wandb\sdk\lib\sock_client.py", line 146, in send_server_request
    self._send_message(msg)
  File "C:\Users\faiso\AppData\Local\Programs\Python\Python312\Lib\site-packages\wandb\sdk\lib\sock_client.py", line 143, in _send_message
    self._sendall_with_error_handle(header + data)
  File "C:\Users\faiso\AppData\Local\Programs\Python\Python312\Lib\site-packages\wandb\sdk\lib\sock_client.py", line 122, in _sendall_with_error_handle
    sent = self._sock.send(data)
           ^^^^^^^^^^^^^^^^^^^^^
ConnectionAbortedError: [WinError 10053] An established connection was aborted by the software in your host machine
2025-09-25 15:20:50,420 ERROR   MainThread:2392 [redirect.py:_on_write():664] [all runs] error in stdout callback
Traceback (most recent call last):
  File "C:\Users\faiso\AppData\Local\Programs\Python\Python312\Lib\site-packages\wandb\sdk\lib\redirect.py", line 662, in _on_write
    cb(written_data)
  File "C:\Users\faiso\AppData\Local\Programs\Python\Python312\Lib\site-packages\wandb\sdk\wandb_run.py", line 2415, in <lambda>
    lambda data: self._console_raw_callback("stdout", data),
                 ^^^^^^^^^^^^^^^^^^^^^^^^^^^^^^^^^^^^^^^^^^
  File "C:\Users\faiso\AppData\Local\Programs\Python\Python312\Lib\site-packages\wandb\sdk\wandb_run.py", line 399, in wrapper
    return func(self, *args, **kwargs)
           ^^^^^^^^^^^^^^^^^^^^^^^^^^^
  File "C:\Users\faiso\AppData\Local\Programs\Python\Python312\Lib\site-packages\wandb\sdk\wandb_run.py", line 457, in wrapper_fn
    return func(self, *args, **kwargs)
           ^^^^^^^^^^^^^^^^^^^^^^^^^^^
  File "C:\Users\faiso\AppData\Local\Programs\Python\Python312\Lib\site-packages\wandb\sdk\wandb_run.py", line 1583, in _console_raw_callback
    self._backend.interface.publish_output_raw(name, data)
  File "C:\Users\faiso\AppData\Local\Programs\Python\Python312\Lib\site-packages\wandb\sdk\interface\interface.py", line 771, in publish_output_raw
    self._publish_output_raw(o)
  File "C:\Users\faiso\AppData\Local\Programs\Python\Python312\Lib\site-packages\wandb\sdk\interface\interface_shared.py", line 38, in _publish_output_raw
    self._publish(rec)
  File "C:\Users\faiso\AppData\Local\Programs\Python\Python312\Lib\site-packages\wandb\sdk\interface\interface_sock.py", line 39, in _publish
    self._sock_client.send_record_publish(record)
  File "C:\Users\faiso\AppData\Local\Programs\Python\Python312\Lib\site-packages\wandb\sdk\lib\sock_client.py", line 166, in send_record_publish
    self.send_server_request(server_req)
  File "C:\Users\faiso\AppData\Local\Programs\Python\Python312\Lib\site-packages\wandb\sdk\lib\sock_client.py", line 146, in send_server_request
    self._send_message(msg)
  File "C:\Users\faiso\AppData\Local\Programs\Python\Python312\Lib\site-packages\wandb\sdk\lib\sock_client.py", line 143, in _send_message
    self._sendall_with_error_handle(header + data)
  File "C:\Users\faiso\AppData\Local\Programs\Python\Python312\Lib\site-packages\wandb\sdk\lib\sock_client.py", line 122, in _sendall_with_error_handle
    sent = self._sock.send(data)
           ^^^^^^^^^^^^^^^^^^^^^
ConnectionAbortedError: [WinError 10053] An established connection was aborted by the software in your host machine
2025-09-25 15:20:50,420 ERROR   MainThread:2392 [redirect.py:_on_write():664] [all runs] error in stdout callback
Traceback (most recent call last):
  File "C:\Users\faiso\AppData\Local\Programs\Python\Python312\Lib\site-packages\wandb\sdk\lib\redirect.py", line 662, in _on_write
    cb(written_data)
  File "C:\Users\faiso\AppData\Local\Programs\Python\Python312\Lib\site-packages\wandb\sdk\wandb_run.py", line 2415, in <lambda>
    lambda data: self._console_raw_callback("stdout", data),
                 ^^^^^^^^^^^^^^^^^^^^^^^^^^^^^^^^^^^^^^^^^^
  File "C:\Users\faiso\AppData\Local\Programs\Python\Python312\Lib\site-packages\wandb\sdk\wandb_run.py", line 399, in wrapper
    return func(self, *args, **kwargs)
           ^^^^^^^^^^^^^^^^^^^^^^^^^^^
  File "C:\Users\faiso\AppData\Local\Programs\Python\Python312\Lib\site-packages\wandb\sdk\wandb_run.py", line 457, in wrapper_fn
    return func(self, *args, **kwargs)
           ^^^^^^^^^^^^^^^^^^^^^^^^^^^
  File "C:\Users\faiso\AppData\Local\Programs\Python\Python312\Lib\site-packages\wandb\sdk\wandb_run.py", line 1583, in _console_raw_callback
    self._backend.interface.publish_output_raw(name, data)
  File "C:\Users\faiso\AppData\Local\Programs\Python\Python312\Lib\site-packages\wandb\sdk\interface\interface.py", line 771, in publish_output_raw
    self._publish_output_raw(o)
  File "C:\Users\faiso\AppData\Local\Programs\Python\Python312\Lib\site-packages\wandb\sdk\interface\interface_shared.py", line 38, in _publish_output_raw
    self._publish(rec)
  File "C:\Users\faiso\AppData\Local\Programs\Python\Python312\Lib\site-packages\wandb\sdk\interface\interface_sock.py", line 39, in _publish
    self._sock_client.send_record_publish(record)
  File "C:\Users\faiso\AppData\Local\Programs\Python\Python312\Lib\site-packages\wandb\sdk\lib\sock_client.py", line 166, in send_record_publish
    self.send_server_request(server_req)
  File "C:\Users\faiso\AppData\Local\Programs\Python\Python312\Lib\site-packages\wandb\sdk\lib\sock_client.py", line 146, in send_server_request
    self._send_message(msg)
  File "C:\Users\faiso\AppData\Local\Programs\Python\Python312\Lib\site-packages\wandb\sdk\lib\sock_client.py", line 143, in _send_message
    self._sendall_with_error_handle(header + data)
  File "C:\Users\faiso\AppData\Local\Programs\Python\Python312\Lib\site-packages\wandb\sdk\lib\sock_client.py", line 122, in _sendall_with_error_handle
    sent = self._sock.send(data)
           ^^^^^^^^^^^^^^^^^^^^^
ConnectionAbortedError: [WinError 10053] An established connection was aborted by the software in your host machine
2025-09-25 15:20:50,420 ERROR   MainThread:2392 [redirect.py:_on_write():664] [all runs] error in stdout callback
Traceback (most recent call last):
  File "C:\Users\faiso\AppData\Local\Programs\Python\Python312\Lib\site-packages\wandb\sdk\lib\redirect.py", line 662, in _on_write
    cb(written_data)
  File "C:\Users\faiso\AppData\Local\Programs\Python\Python312\Lib\site-packages\wandb\sdk\wandb_run.py", line 2415, in <lambda>
    lambda data: self._console_raw_callback("stdout", data),
                 ^^^^^^^^^^^^^^^^^^^^^^^^^^^^^^^^^^^^^^^^^^
  File "C:\Users\faiso\AppData\Local\Programs\Python\Python312\Lib\site-packages\wandb\sdk\wandb_run.py", line 399, in wrapper
    return func(self, *args, **kwargs)
           ^^^^^^^^^^^^^^^^^^^^^^^^^^^
  File "C:\Users\faiso\AppData\Local\Programs\Python\Python312\Lib\site-packages\wandb\sdk\wandb_run.py", line 457, in wrapper_fn
    return func(self, *args, **kwargs)
           ^^^^^^^^^^^^^^^^^^^^^^^^^^^
  File "C:\Users\faiso\AppData\Local\Programs\Python\Python312\Lib\site-packages\wandb\sdk\wandb_run.py", line 1583, in _console_raw_callback
    self._backend.interface.publish_output_raw(name, data)
  File "C:\Users\faiso\AppData\Local\Programs\Python\Python312\Lib\site-packages\wandb\sdk\interface\interface.py", line 771, in publish_output_raw
    self._publish_output_raw(o)
  File "C:\Users\faiso\AppData\Local\Programs\Python\Python312\Lib\site-packages\wandb\sdk\interface\interface_shared.py", line 38, in _publish_output_raw
    self._publish(rec)
  File "C:\Users\faiso\AppData\Local\Programs\Python\Python312\Lib\site-packages\wandb\sdk\interface\interface_sock.py", line 39, in _publish
    self._sock_client.send_record_publish(record)
  File "C:\Users\faiso\AppData\Local\Programs\Python\Python312\Lib\site-packages\wandb\sdk\lib\sock_client.py", line 166, in send_record_publish
    self.send_server_request(server_req)
  File "C:\Users\faiso\AppData\Local\Programs\Python\Python312\Lib\site-packages\wandb\sdk\lib\sock_client.py", line 146, in send_server_request
    self._send_message(msg)
  File "C:\Users\faiso\AppData\Local\Programs\Python\Python312\Lib\site-packages\wandb\sdk\lib\sock_client.py", line 143, in _send_message
    self._sendall_with_error_handle(header + data)
  File "C:\Users\faiso\AppData\Local\Programs\Python\Python312\Lib\site-packages\wandb\sdk\lib\sock_client.py", line 122, in _sendall_with_error_handle
    sent = self._sock.send(data)
           ^^^^^^^^^^^^^^^^^^^^^
ConnectionAbortedError: [WinError 10053] An established connection was aborted by the software in your host machine
2025-09-25 15:20:50,424 ERROR   MainThread:2392 [redirect.py:_on_write():664] [all runs] error in stdout callback
Traceback (most recent call last):
  File "C:\Users\faiso\AppData\Local\Programs\Python\Python312\Lib\site-packages\wandb\sdk\lib\redirect.py", line 662, in _on_write
    cb(written_data)
  File "C:\Users\faiso\AppData\Local\Programs\Python\Python312\Lib\site-packages\wandb\sdk\wandb_run.py", line 2415, in <lambda>
    lambda data: self._console_raw_callback("stdout", data),
                 ^^^^^^^^^^^^^^^^^^^^^^^^^^^^^^^^^^^^^^^^^^
  File "C:\Users\faiso\AppData\Local\Programs\Python\Python312\Lib\site-packages\wandb\sdk\wandb_run.py", line 399, in wrapper
    return func(self, *args, **kwargs)
           ^^^^^^^^^^^^^^^^^^^^^^^^^^^
  File "C:\Users\faiso\AppData\Local\Programs\Python\Python312\Lib\site-packages\wandb\sdk\wandb_run.py", line 457, in wrapper_fn
    return func(self, *args, **kwargs)
           ^^^^^^^^^^^^^^^^^^^^^^^^^^^
  File "C:\Users\faiso\AppData\Local\Programs\Python\Python312\Lib\site-packages\wandb\sdk\wandb_run.py", line 1583, in _console_raw_callback
    self._backend.interface.publish_output_raw(name, data)
  File "C:\Users\faiso\AppData\Local\Programs\Python\Python312\Lib\site-packages\wandb\sdk\interface\interface.py", line 771, in publish_output_raw
    self._publish_output_raw(o)
  File "C:\Users\faiso\AppData\Local\Programs\Python\Python312\Lib\site-packages\wandb\sdk\interface\interface_shared.py", line 38, in _publish_output_raw
    self._publish(rec)
  File "C:\Users\faiso\AppData\Local\Programs\Python\Python312\Lib\site-packages\wandb\sdk\interface\interface_sock.py", line 39, in _publish
    self._sock_client.send_record_publish(record)
  File "C:\Users\faiso\AppData\Local\Programs\Python\Python312\Lib\site-packages\wandb\sdk\lib\sock_client.py", line 166, in send_record_publish
    self.send_server_request(server_req)
  File "C:\Users\faiso\AppData\Local\Programs\Python\Python312\Lib\site-packages\wandb\sdk\lib\sock_client.py", line 146, in send_server_request
    self._send_message(msg)
  File "C:\Users\faiso\AppData\Local\Programs\Python\Python312\Lib\site-packages\wandb\sdk\lib\sock_client.py", line 143, in _send_message
    self._sendall_with_error_handle(header + data)
  File "C:\Users\faiso\AppData\Local\Programs\Python\Python312\Lib\site-packages\wandb\sdk\lib\sock_client.py", line 122, in _sendall_with_error_handle
    sent = self._sock.send(data)
           ^^^^^^^^^^^^^^^^^^^^^
ConnectionAbortedError: [WinError 10053] An established connection was aborted by the software in your host machine
