2025-08-28 13:10:47,930 INFO    MainThread:1712 [wandb_setup.py:_flush():80] Current SDK version is 0.21.1
2025-08-28 13:10:47,930 INFO    MainThread:1712 [wandb_setup.py:_flush():80] Configure stats pid to 1712
2025-08-28 13:10:47,930 INFO    MainThread:1712 [wandb_setup.py:_flush():80] Loading settings from C:\Users\faiso\.config\wandb\settings
2025-08-28 13:10:47,930 INFO    MainThread:1712 [wandb_setup.py:_flush():80] Loading settings from D:\COMP702\DIFUSCO-main\difusco\wandb\settings
2025-08-28 13:10:47,930 INFO    MainThread:1712 [wandb_setup.py:_flush():80] Loading settings from environment variables
2025-08-28 13:10:47,930 INFO    MainThread:1712 [wandb_init.py:setup_run_log_directory():703] Logging user logs to results\models\wandb\run-20250828_131047-sfcxu4rx\logs\debug.log
2025-08-28 13:10:47,930 INFO    MainThread:1712 [wandb_init.py:setup_run_log_directory():704] Logging internal logs to results\models\wandb\run-20250828_131047-sfcxu4rx\logs\debug-internal.log
2025-08-28 13:10:47,930 INFO    MainThread:1712 [wandb_init.py:init():830] calling init triggers
2025-08-28 13:10:47,930 INFO    MainThread:1712 [wandb_init.py:init():835] wandb.init called with sweep_config: {}
config: {'_wandb': {}}
2025-08-28 13:10:47,930 INFO    MainThread:1712 [wandb_init.py:init():871] starting backend
2025-08-28 13:10:48,299 INFO    MainThread:1712 [wandb_init.py:init():874] sending inform_init request
2025-08-28 13:10:48,318 INFO    MainThread:1712 [wandb_init.py:init():882] backend started and connected
2025-08-28 13:10:48,334 INFO    MainThread:1712 [wandb_init.py:init():953] updated telemetry
2025-08-28 13:10:48,335 INFO    MainThread:1712 [wandb_init.py:init():977] communicating run to backend with 90.0 second timeout
2025-08-28 13:10:49,123 INFO    MainThread:1712 [wandb_init.py:init():1029] starting run threads in backend
2025-08-28 13:10:49,365 INFO    MainThread:1712 [wandb_run.py:_console_start():2494] atexit reg
2025-08-28 13:10:49,366 INFO    MainThread:1712 [wandb_run.py:_redirect():2342] redirect: wrap_raw
2025-08-28 13:10:49,366 INFO    MainThread:1712 [wandb_run.py:_redirect():2411] Wrapping output streams.
2025-08-28 13:10:49,366 INFO    MainThread:1712 [wandb_run.py:_redirect():2434] Redirects installed.
2025-08-28 13:10:49,369 INFO    MainThread:1712 [wandb_init.py:init():1075] run started, returning control to user process
2025-08-28 13:13:06,906 WARNING MsgRouterThr:1712 [router.py:message_loop():63] [no run ID] message_loop has been closed
Traceback (most recent call last):
  File "C:\Users\faiso\AppData\Local\Programs\Python\Python312\Lib\site-packages\wandb\sdk\lib\sock_client.py", line 200, in _read_packet_bytes
    data = self._sock.recv(self._bufsize)
           ^^^^^^^^^^^^^^^^^^^^^^^^^^^^^^
ConnectionResetError: [WinError 10054] An existing connection was forcibly closed by the remote host

The above exception was the direct cause of the following exception:

Traceback (most recent call last):
  File "C:\Users\faiso\AppData\Local\Programs\Python\Python312\Lib\site-packages\wandb\sdk\interface\router_sock.py", line 27, in _read_message
    return self._sock_client.read_server_response(timeout=1)
           ^^^^^^^^^^^^^^^^^^^^^^^^^^^^^^^^^^^^^^^^^^^^^^^^^
  File "C:\Users\faiso\AppData\Local\Programs\Python\Python312\Lib\site-packages\wandb\sdk\lib\sock_client.py", line 227, in read_server_response
    data = self._read_packet_bytes(timeout=timeout)
           ^^^^^^^^^^^^^^^^^^^^^^^^^^^^^^^^^^^^^^^^
  File "C:\Users\faiso\AppData\Local\Programs\Python\Python312\Lib\site-packages\wandb\sdk\lib\sock_client.py", line 204, in _read_packet_bytes
    raise SockClientClosedError from e
wandb.sdk.lib.sock_client.SockClientClosedError

The above exception was the direct cause of the following exception:

Traceback (most recent call last):
  File "C:\Users\faiso\AppData\Local\Programs\Python\Python312\Lib\site-packages\wandb\sdk\interface\router.py", line 56, in message_loop
    msg = self._read_message()
          ^^^^^^^^^^^^^^^^^^^^
  File "C:\Users\faiso\AppData\Local\Programs\Python\Python312\Lib\site-packages\wandb\sdk\interface\router_sock.py", line 29, in _read_message
    raise MessageRouterClosedError from e
wandb.sdk.interface.router.MessageRouterClosedError
2025-08-28 13:13:06,925 INFO    MsgRouterThr:1712 [mailbox.py:close():129] [no run ID] Closing mailbox, abandoning 1 handles.
2025-08-28 13:14:47,813 ERROR   MainThread:1712 [redirect.py:_on_write():664] [all runs] error in stdout callback
Traceback (most recent call last):
  File "C:\Users\faiso\AppData\Local\Programs\Python\Python312\Lib\site-packages\wandb\sdk\lib\redirect.py", line 662, in _on_write
    cb(written_data)
  File "C:\Users\faiso\AppData\Local\Programs\Python\Python312\Lib\site-packages\wandb\sdk\wandb_run.py", line 2415, in <lambda>
    lambda data: self._console_raw_callback("stdout", data),
                 ^^^^^^^^^^^^^^^^^^^^^^^^^^^^^^^^^^^^^^^^^^
  File "C:\Users\faiso\AppData\Local\Programs\Python\Python312\Lib\site-packages\wandb\sdk\wandb_run.py", line 399, in wrapper
    return func(self, *args, **kwargs)
           ^^^^^^^^^^^^^^^^^^^^^^^^^^^
  File "C:\Users\faiso\AppData\Local\Programs\Python\Python312\Lib\site-packages\wandb\sdk\wandb_run.py", line 457, in wrapper_fn
    return func(self, *args, **kwargs)
           ^^^^^^^^^^^^^^^^^^^^^^^^^^^
  File "C:\Users\faiso\AppData\Local\Programs\Python\Python312\Lib\site-packages\wandb\sdk\wandb_run.py", line 1583, in _console_raw_callback
    self._backend.interface.publish_output_raw(name, data)
  File "C:\Users\faiso\AppData\Local\Programs\Python\Python312\Lib\site-packages\wandb\sdk\interface\interface.py", line 771, in publish_output_raw
    self._publish_output_raw(o)
  File "C:\Users\faiso\AppData\Local\Programs\Python\Python312\Lib\site-packages\wandb\sdk\interface\interface_shared.py", line 38, in _publish_output_raw
    self._publish(rec)
  File "C:\Users\faiso\AppData\Local\Programs\Python\Python312\Lib\site-packages\wandb\sdk\interface\interface_sock.py", line 39, in _publish
    self._sock_client.send_record_publish(record)
  File "C:\Users\faiso\AppData\Local\Programs\Python\Python312\Lib\site-packages\wandb\sdk\lib\sock_client.py", line 166, in send_record_publish
    self.send_server_request(server_req)
  File "C:\Users\faiso\AppData\Local\Programs\Python\Python312\Lib\site-packages\wandb\sdk\lib\sock_client.py", line 146, in send_server_request
    self._send_message(msg)
  File "C:\Users\faiso\AppData\Local\Programs\Python\Python312\Lib\site-packages\wandb\sdk\lib\sock_client.py", line 143, in _send_message
    self._sendall_with_error_handle(header + data)
  File "C:\Users\faiso\AppData\Local\Programs\Python\Python312\Lib\site-packages\wandb\sdk\lib\sock_client.py", line 122, in _sendall_with_error_handle
    sent = self._sock.send(data)
           ^^^^^^^^^^^^^^^^^^^^^
ConnectionResetError: [WinError 10054] An existing connection was forcibly closed by the remote host
2025-08-28 13:14:47,907 ERROR   MainThread:1712 [redirect.py:_on_write():664] [all runs] error in stdout callback
Traceback (most recent call last):
  File "C:\Users\faiso\AppData\Local\Programs\Python\Python312\Lib\site-packages\wandb\sdk\lib\redirect.py", line 662, in _on_write
    cb(written_data)
  File "C:\Users\faiso\AppData\Local\Programs\Python\Python312\Lib\site-packages\wandb\sdk\wandb_run.py", line 2415, in <lambda>
    lambda data: self._console_raw_callback("stdout", data),
                 ^^^^^^^^^^^^^^^^^^^^^^^^^^^^^^^^^^^^^^^^^^
  File "C:\Users\faiso\AppData\Local\Programs\Python\Python312\Lib\site-packages\wandb\sdk\wandb_run.py", line 399, in wrapper
    return func(self, *args, **kwargs)
           ^^^^^^^^^^^^^^^^^^^^^^^^^^^
  File "C:\Users\faiso\AppData\Local\Programs\Python\Python312\Lib\site-packages\wandb\sdk\wandb_run.py", line 457, in wrapper_fn
    return func(self, *args, **kwargs)
           ^^^^^^^^^^^^^^^^^^^^^^^^^^^
  File "C:\Users\faiso\AppData\Local\Programs\Python\Python312\Lib\site-packages\wandb\sdk\wandb_run.py", line 1583, in _console_raw_callback
    self._backend.interface.publish_output_raw(name, data)
  File "C:\Users\faiso\AppData\Local\Programs\Python\Python312\Lib\site-packages\wandb\sdk\interface\interface.py", line 771, in publish_output_raw
    self._publish_output_raw(o)
  File "C:\Users\faiso\AppData\Local\Programs\Python\Python312\Lib\site-packages\wandb\sdk\interface\interface_shared.py", line 38, in _publish_output_raw
    self._publish(rec)
  File "C:\Users\faiso\AppData\Local\Programs\Python\Python312\Lib\site-packages\wandb\sdk\interface\interface_sock.py", line 39, in _publish
    self._sock_client.send_record_publish(record)
  File "C:\Users\faiso\AppData\Local\Programs\Python\Python312\Lib\site-packages\wandb\sdk\lib\sock_client.py", line 166, in send_record_publish
    self.send_server_request(server_req)
  File "C:\Users\faiso\AppData\Local\Programs\Python\Python312\Lib\site-packages\wandb\sdk\lib\sock_client.py", line 146, in send_server_request
    self._send_message(msg)
  File "C:\Users\faiso\AppData\Local\Programs\Python\Python312\Lib\site-packages\wandb\sdk\lib\sock_client.py", line 143, in _send_message
    self._sendall_with_error_handle(header + data)
  File "C:\Users\faiso\AppData\Local\Programs\Python\Python312\Lib\site-packages\wandb\sdk\lib\sock_client.py", line 122, in _sendall_with_error_handle
    sent = self._sock.send(data)
           ^^^^^^^^^^^^^^^^^^^^^
ConnectionResetError: [WinError 10054] An existing connection was forcibly closed by the remote host
2025-08-28 13:17:26,007 ERROR   MainThread:1712 [redirect.py:_on_write():664] [all runs] error in stdout callback
Traceback (most recent call last):
  File "C:\Users\faiso\AppData\Local\Programs\Python\Python312\Lib\site-packages\wandb\sdk\lib\redirect.py", line 662, in _on_write
    cb(written_data)
  File "C:\Users\faiso\AppData\Local\Programs\Python\Python312\Lib\site-packages\wandb\sdk\wandb_run.py", line 2415, in <lambda>
    lambda data: self._console_raw_callback("stdout", data),
                 ^^^^^^^^^^^^^^^^^^^^^^^^^^^^^^^^^^^^^^^^^^
  File "C:\Users\faiso\AppData\Local\Programs\Python\Python312\Lib\site-packages\wandb\sdk\wandb_run.py", line 399, in wrapper
    return func(self, *args, **kwargs)
           ^^^^^^^^^^^^^^^^^^^^^^^^^^^
  File "C:\Users\faiso\AppData\Local\Programs\Python\Python312\Lib\site-packages\wandb\sdk\wandb_run.py", line 457, in wrapper_fn
    return func(self, *args, **kwargs)
           ^^^^^^^^^^^^^^^^^^^^^^^^^^^
  File "C:\Users\faiso\AppData\Local\Programs\Python\Python312\Lib\site-packages\wandb\sdk\wandb_run.py", line 1583, in _console_raw_callback
    self._backend.interface.publish_output_raw(name, data)
  File "C:\Users\faiso\AppData\Local\Programs\Python\Python312\Lib\site-packages\wandb\sdk\interface\interface.py", line 771, in publish_output_raw
    self._publish_output_raw(o)
  File "C:\Users\faiso\AppData\Local\Programs\Python\Python312\Lib\site-packages\wandb\sdk\interface\interface_shared.py", line 38, in _publish_output_raw
    self._publish(rec)
  File "C:\Users\faiso\AppData\Local\Programs\Python\Python312\Lib\site-packages\wandb\sdk\interface\interface_sock.py", line 39, in _publish
    self._sock_client.send_record_publish(record)
  File "C:\Users\faiso\AppData\Local\Programs\Python\Python312\Lib\site-packages\wandb\sdk\lib\sock_client.py", line 166, in send_record_publish
    self.send_server_request(server_req)
  File "C:\Users\faiso\AppData\Local\Programs\Python\Python312\Lib\site-packages\wandb\sdk\lib\sock_client.py", line 146, in send_server_request
    self._send_message(msg)
  File "C:\Users\faiso\AppData\Local\Programs\Python\Python312\Lib\site-packages\wandb\sdk\lib\sock_client.py", line 143, in _send_message
    self._sendall_with_error_handle(header + data)
  File "C:\Users\faiso\AppData\Local\Programs\Python\Python312\Lib\site-packages\wandb\sdk\lib\sock_client.py", line 122, in _sendall_with_error_handle
    sent = self._sock.send(data)
           ^^^^^^^^^^^^^^^^^^^^^
ConnectionResetError: [WinError 10054] An existing connection was forcibly closed by the remote host
2025-08-28 13:17:26,023 ERROR   MainThread:1712 [redirect.py:_on_write():664] [all runs] error in stdout callback
Traceback (most recent call last):
  File "C:\Users\faiso\AppData\Local\Programs\Python\Python312\Lib\site-packages\wandb\sdk\lib\redirect.py", line 662, in _on_write
    cb(written_data)
  File "C:\Users\faiso\AppData\Local\Programs\Python\Python312\Lib\site-packages\wandb\sdk\wandb_run.py", line 2415, in <lambda>
    lambda data: self._console_raw_callback("stdout", data),
                 ^^^^^^^^^^^^^^^^^^^^^^^^^^^^^^^^^^^^^^^^^^
  File "C:\Users\faiso\AppData\Local\Programs\Python\Python312\Lib\site-packages\wandb\sdk\wandb_run.py", line 399, in wrapper
    return func(self, *args, **kwargs)
           ^^^^^^^^^^^^^^^^^^^^^^^^^^^
  File "C:\Users\faiso\AppData\Local\Programs\Python\Python312\Lib\site-packages\wandb\sdk\wandb_run.py", line 457, in wrapper_fn
    return func(self, *args, **kwargs)
           ^^^^^^^^^^^^^^^^^^^^^^^^^^^
  File "C:\Users\faiso\AppData\Local\Programs\Python\Python312\Lib\site-packages\wandb\sdk\wandb_run.py", line 1583, in _console_raw_callback
    self._backend.interface.publish_output_raw(name, data)
  File "C:\Users\faiso\AppData\Local\Programs\Python\Python312\Lib\site-packages\wandb\sdk\interface\interface.py", line 771, in publish_output_raw
    self._publish_output_raw(o)
  File "C:\Users\faiso\AppData\Local\Programs\Python\Python312\Lib\site-packages\wandb\sdk\interface\interface_shared.py", line 38, in _publish_output_raw
    self._publish(rec)
  File "C:\Users\faiso\AppData\Local\Programs\Python\Python312\Lib\site-packages\wandb\sdk\interface\interface_sock.py", line 39, in _publish
    self._sock_client.send_record_publish(record)
  File "C:\Users\faiso\AppData\Local\Programs\Python\Python312\Lib\site-packages\wandb\sdk\lib\sock_client.py", line 166, in send_record_publish
    self.send_server_request(server_req)
  File "C:\Users\faiso\AppData\Local\Programs\Python\Python312\Lib\site-packages\wandb\sdk\lib\sock_client.py", line 146, in send_server_request
    self._send_message(msg)
  File "C:\Users\faiso\AppData\Local\Programs\Python\Python312\Lib\site-packages\wandb\sdk\lib\sock_client.py", line 143, in _send_message
    self._sendall_with_error_handle(header + data)
  File "C:\Users\faiso\AppData\Local\Programs\Python\Python312\Lib\site-packages\wandb\sdk\lib\sock_client.py", line 122, in _sendall_with_error_handle
    sent = self._sock.send(data)
           ^^^^^^^^^^^^^^^^^^^^^
ConnectionResetError: [WinError 10054] An existing connection was forcibly closed by the remote host
2025-08-28 13:17:26,023 ERROR   MainThread:1712 [redirect.py:_on_write():664] [all runs] error in stdout callback
Traceback (most recent call last):
  File "C:\Users\faiso\AppData\Local\Programs\Python\Python312\Lib\site-packages\wandb\sdk\lib\redirect.py", line 662, in _on_write
    cb(written_data)
  File "C:\Users\faiso\AppData\Local\Programs\Python\Python312\Lib\site-packages\wandb\sdk\wandb_run.py", line 2415, in <lambda>
    lambda data: self._console_raw_callback("stdout", data),
                 ^^^^^^^^^^^^^^^^^^^^^^^^^^^^^^^^^^^^^^^^^^
  File "C:\Users\faiso\AppData\Local\Programs\Python\Python312\Lib\site-packages\wandb\sdk\wandb_run.py", line 399, in wrapper
    return func(self, *args, **kwargs)
           ^^^^^^^^^^^^^^^^^^^^^^^^^^^
  File "C:\Users\faiso\AppData\Local\Programs\Python\Python312\Lib\site-packages\wandb\sdk\wandb_run.py", line 457, in wrapper_fn
    return func(self, *args, **kwargs)
           ^^^^^^^^^^^^^^^^^^^^^^^^^^^
  File "C:\Users\faiso\AppData\Local\Programs\Python\Python312\Lib\site-packages\wandb\sdk\wandb_run.py", line 1583, in _console_raw_callback
    self._backend.interface.publish_output_raw(name, data)
  File "C:\Users\faiso\AppData\Local\Programs\Python\Python312\Lib\site-packages\wandb\sdk\interface\interface.py", line 771, in publish_output_raw
    self._publish_output_raw(o)
  File "C:\Users\faiso\AppData\Local\Programs\Python\Python312\Lib\site-packages\wandb\sdk\interface\interface_shared.py", line 38, in _publish_output_raw
    self._publish(rec)
  File "C:\Users\faiso\AppData\Local\Programs\Python\Python312\Lib\site-packages\wandb\sdk\interface\interface_sock.py", line 39, in _publish
    self._sock_client.send_record_publish(record)
  File "C:\Users\faiso\AppData\Local\Programs\Python\Python312\Lib\site-packages\wandb\sdk\lib\sock_client.py", line 166, in send_record_publish
    self.send_server_request(server_req)
  File "C:\Users\faiso\AppData\Local\Programs\Python\Python312\Lib\site-packages\wandb\sdk\lib\sock_client.py", line 146, in send_server_request
    self._send_message(msg)
  File "C:\Users\faiso\AppData\Local\Programs\Python\Python312\Lib\site-packages\wandb\sdk\lib\sock_client.py", line 143, in _send_message
    self._sendall_with_error_handle(header + data)
  File "C:\Users\faiso\AppData\Local\Programs\Python\Python312\Lib\site-packages\wandb\sdk\lib\sock_client.py", line 122, in _sendall_with_error_handle
    sent = self._sock.send(data)
           ^^^^^^^^^^^^^^^^^^^^^
ConnectionResetError: [WinError 10054] An existing connection was forcibly closed by the remote host
2025-08-28 13:17:26,023 ERROR   MainThread:1712 [redirect.py:_on_write():664] [all runs] error in stdout callback
Traceback (most recent call last):
  File "C:\Users\faiso\AppData\Local\Programs\Python\Python312\Lib\site-packages\wandb\sdk\lib\redirect.py", line 662, in _on_write
    cb(written_data)
  File "C:\Users\faiso\AppData\Local\Programs\Python\Python312\Lib\site-packages\wandb\sdk\wandb_run.py", line 2415, in <lambda>
    lambda data: self._console_raw_callback("stdout", data),
                 ^^^^^^^^^^^^^^^^^^^^^^^^^^^^^^^^^^^^^^^^^^
  File "C:\Users\faiso\AppData\Local\Programs\Python\Python312\Lib\site-packages\wandb\sdk\wandb_run.py", line 399, in wrapper
    return func(self, *args, **kwargs)
           ^^^^^^^^^^^^^^^^^^^^^^^^^^^
  File "C:\Users\faiso\AppData\Local\Programs\Python\Python312\Lib\site-packages\wandb\sdk\wandb_run.py", line 457, in wrapper_fn
    return func(self, *args, **kwargs)
           ^^^^^^^^^^^^^^^^^^^^^^^^^^^
  File "C:\Users\faiso\AppData\Local\Programs\Python\Python312\Lib\site-packages\wandb\sdk\wandb_run.py", line 1583, in _console_raw_callback
    self._backend.interface.publish_output_raw(name, data)
  File "C:\Users\faiso\AppData\Local\Programs\Python\Python312\Lib\site-packages\wandb\sdk\interface\interface.py", line 771, in publish_output_raw
    self._publish_output_raw(o)
  File "C:\Users\faiso\AppData\Local\Programs\Python\Python312\Lib\site-packages\wandb\sdk\interface\interface_shared.py", line 38, in _publish_output_raw
    self._publish(rec)
  File "C:\Users\faiso\AppData\Local\Programs\Python\Python312\Lib\site-packages\wandb\sdk\interface\interface_sock.py", line 39, in _publish
    self._sock_client.send_record_publish(record)
  File "C:\Users\faiso\AppData\Local\Programs\Python\Python312\Lib\site-packages\wandb\sdk\lib\sock_client.py", line 166, in send_record_publish
    self.send_server_request(server_req)
  File "C:\Users\faiso\AppData\Local\Programs\Python\Python312\Lib\site-packages\wandb\sdk\lib\sock_client.py", line 146, in send_server_request
    self._send_message(msg)
  File "C:\Users\faiso\AppData\Local\Programs\Python\Python312\Lib\site-packages\wandb\sdk\lib\sock_client.py", line 143, in _send_message
    self._sendall_with_error_handle(header + data)
  File "C:\Users\faiso\AppData\Local\Programs\Python\Python312\Lib\site-packages\wandb\sdk\lib\sock_client.py", line 122, in _sendall_with_error_handle
    sent = self._sock.send(data)
           ^^^^^^^^^^^^^^^^^^^^^
ConnectionResetError: [WinError 10054] An existing connection was forcibly closed by the remote host
2025-08-28 13:17:26,044 ERROR   MainThread:1712 [redirect.py:_on_write():664] [all runs] error in stderr callback
Traceback (most recent call last):
  File "C:\Users\faiso\AppData\Local\Programs\Python\Python312\Lib\site-packages\wandb\sdk\lib\redirect.py", line 662, in _on_write
    cb(written_data)
  File "C:\Users\faiso\AppData\Local\Programs\Python\Python312\Lib\site-packages\wandb\sdk\wandb_run.py", line 2421, in <lambda>
    lambda data: self._console_raw_callback("stderr", data),
                 ^^^^^^^^^^^^^^^^^^^^^^^^^^^^^^^^^^^^^^^^^^
  File "C:\Users\faiso\AppData\Local\Programs\Python\Python312\Lib\site-packages\wandb\sdk\wandb_run.py", line 399, in wrapper
    return func(self, *args, **kwargs)
           ^^^^^^^^^^^^^^^^^^^^^^^^^^^
  File "C:\Users\faiso\AppData\Local\Programs\Python\Python312\Lib\site-packages\wandb\sdk\wandb_run.py", line 457, in wrapper_fn
    return func(self, *args, **kwargs)
           ^^^^^^^^^^^^^^^^^^^^^^^^^^^
  File "C:\Users\faiso\AppData\Local\Programs\Python\Python312\Lib\site-packages\wandb\sdk\wandb_run.py", line 1583, in _console_raw_callback
    self._backend.interface.publish_output_raw(name, data)
  File "C:\Users\faiso\AppData\Local\Programs\Python\Python312\Lib\site-packages\wandb\sdk\interface\interface.py", line 771, in publish_output_raw
    self._publish_output_raw(o)
  File "C:\Users\faiso\AppData\Local\Programs\Python\Python312\Lib\site-packages\wandb\sdk\interface\interface_shared.py", line 38, in _publish_output_raw
    self._publish(rec)
  File "C:\Users\faiso\AppData\Local\Programs\Python\Python312\Lib\site-packages\wandb\sdk\interface\interface_sock.py", line 39, in _publish
    self._sock_client.send_record_publish(record)
  File "C:\Users\faiso\AppData\Local\Programs\Python\Python312\Lib\site-packages\wandb\sdk\lib\sock_client.py", line 166, in send_record_publish
    self.send_server_request(server_req)
  File "C:\Users\faiso\AppData\Local\Programs\Python\Python312\Lib\site-packages\wandb\sdk\lib\sock_client.py", line 146, in send_server_request
    self._send_message(msg)
  File "C:\Users\faiso\AppData\Local\Programs\Python\Python312\Lib\site-packages\wandb\sdk\lib\sock_client.py", line 143, in _send_message
    self._sendall_with_error_handle(header + data)
  File "C:\Users\faiso\AppData\Local\Programs\Python\Python312\Lib\site-packages\wandb\sdk\lib\sock_client.py", line 122, in _sendall_with_error_handle
    sent = self._sock.send(data)
           ^^^^^^^^^^^^^^^^^^^^^
ConnectionResetError: [WinError 10054] An existing connection was forcibly closed by the remote host
